Workbook

Sheet Export-Zusammenfassung
B3: Dieses Dokument wurde aus Numbers exportiert und jede Tabelle in ein Excel-Arbeitsblatt umgewandelt. Alle anderen Objekte der einzelnen Numbers-Blätter wurden auf eigene Arbeitsblätter übertragen. Beachte, dass die Formelberechnungen in Excel möglicherweise anders sind.
B7: Name des Numbers-Blatts | C7: Numbers-Tabellenname | D7: Name des Excel-Arbeitsblatts
B9: Start
C10: Tabelle 1 | D10: Start
B11: Stammdaten_Artikel
C12: Tabelle 1 | D12: Stammdaten_Artikel
B13: Stammdaten_Mitarbeiter
C14: Tabelle 1 | D14: Stammdaten_Mitarbeiter
B15: Bestellungen
C16: Tabelle 1 | D16: Bestellungen
B17: 01_SVERWEIS_WVERWEIS
C18: Tabelle 1 | D18: 01_SVERWEIS_WVERWEIS
B19: 02_INDEX_VERGLEICH
C20: Tabelle 1 | D20: 02_INDEX_VERGLEICH
B21: 03_XVERWEIS_XVERGLEICH
C22: Tabelle 1 | D22: 03_XVERWEIS_XVERGLEICH
B23: 04_Dynamische_Arrays
C24: Tabelle 1 | D24: 04_Dynamische_Arrays
B25: Loesungen
C26: Tabelle 1 | D26: Loesungen

Sheet Start
A1: Uebungsdatei: Stufe 4 - Nachschlage- und Referenzfunktionen
A2: Diese Datei begleitet Stufe 4 deines Excel-Lernplans: SVERWEIS/WVERWEIS, INDEX/VERGLEICH, XVERWEIS/XVERGLEICH und die dynamischen Array-Funktionen FILTER, SORTIEREN, EINDEUTIG und SEQUENZ.
A4: Aufbau der Datei
A5: Stammdaten_Artikel | B5: Stammdatentabelle: 20 Artikel mit Kategorie, Lieferant, Preis, Lagerort.
A6: Stammdaten_Mitarbeiter | B6: Stammdatentabelle: 10 Mitarbeitende mit Abteilung und Stundensatz.
A7: Bestellungen | B7: Bewegungsdaten: 40 Bestellungen, die in allen Uebungen per Lookup mit den Stammdaten verknuepft werden.
A8: 01_SVERWEIS_WVERWEIS | B8: SVERWEIS (exakt und mit Staffeltabelle) sowie WVERWEIS auf eine Quartalstabelle.
A9: 02_INDEX_VERGLEICH | B9: INDEX/VERGLEICH als SVERWEIS-Ersatz und als Loesung fuer die Suche nach links.
A10: 03_XVERWEIS_XVERGLEICH | B10: XVERWEIS als moderner Ersatz, der Parameter wenn_nicht_gefunden, Suchmodus -1.
A11: 04_Dynamische_Arrays | B11: EINDEUTIG, FILTER, SORTIEREN (kombiniert) und SEQUENZ.
A12: Loesungen | B12: Alle Loesungsformeln zu den Uebungszellen, als Text hinterlegt.
A15: Farblegende
B16: Fertige Beispielformel - schau sie dir an und verstehe, wie sie aufgebaut ist.
B17: Deine Uebung - hier sollst du selbst eine Formel eintippen.
B18: Eingabezelle - hier kannst du den Suchwert aendern und beobachten, was passiert.
A21: Tipp
A22: Aendere zum Test eine Artikel-ID oder einen Namen in den Stammdaten - alle Formeln in den Uebungsblaettern aktualisieren sich automatisch. Bei den dynamischen Array-Funktionen (Blatt 04) brauchen die Zellen rechts und unterhalb der Formel Platz zum 'Verteilen' (Spill) - lass sie leer.

Sheet Stammdaten_Artikel
A1: Stammdaten: Artikel
A2: Diese Tabelle ist die Stammdatentabelle fuer alle Nachschlage-Uebungen. Bitte Struktur nicht veraendern (Spaltenreihenfolge wird in den Formeln referenziert).
A4: Artikel-ID | B4: Artikelname | C4: Kategorie | D4: Lieferant | E4: Einkaufspreis (EUR) | F4: Lagerort
A5: A001 | B5: Laptop 14 Zoll | C5: Elektronik | D5: TechSupply GmbH | E5: 650 | F5: Lager A1
A6: A002 | B6: Monitor 24 Zoll | C6: Elektronik | D6: TechSupply GmbH | E6: 180 | F6: Lager A1
A7: A003 | B7: Tastatur kabellos | C7: Elektronik | D7: TechSupply GmbH | E7: 35 | F7: Lager A1
A8: A004 | B8: Maus optisch | C8: Elektronik | D8: TechSupply GmbH | E8: 18 | F8: Lager A1
A9: A005 | B9: USB-C Kabel | C9: IT-Zubehoer | D9: KabelPro AG | E9: 8 | F9: Lager A2
A10: A006 | B10: Headset | C10: Elektronik | D10: TechSupply GmbH | E10: 45 | F10: Lager A1
A11: A007 | B11: Druckerpapier A4 | C11: Bueromaterial | D11: PaperPlus KG | E11: 6 | F11: Lager B1
A12: A008 | B12: Kugelschreiber | C12: Bueromaterial | D12: PaperPlus KG | E12: 1 | F12: Lager B1
A13: A009 | B13: Ordner A4 | C13: Bueromaterial | D13: PaperPlus KG | E13: 2 | F13: Lager B1
A14: A010 | B14: Aktenvernichter | C14: Bueromaterial | D14: OfficeTech GmbH | E14: 120 | F14: Lager B2
A15: A011 | B15: Bohrmaschine | C15: Werkzeug | D15: WerkzeugWelt AG | E15: 95 | F15: Lager C1
A16: A012 | B16: Schraubendreher-Set | C16: Werkzeug | D16: WerkzeugWelt AG | E16: 25 | F16: Lager C1
... A24: A020 | B24: Webcam | C24: Elektronik | D24: TechSupply GmbH | E24: 55 | F24: Lager A1

Sheet Stammdaten_Mitarbeiter
A1: Stammdaten: Mitarbeiter
A2: Zweite Stammdatentabelle - wird fuer Lookup-Uebungen mit Bearbeiter-Zuordnung verwendet.
A4: Mitarbeiter-ID | B4: Name | C4: Abteilung | D4: Stundensatz (EUR)
A5: M01 | B5: Anna Berger | C5: Einkauf | D5: 32
A6: M02 | B6: Jonas Wolf | C6: Einkauf | D6: 32
A7: M03 | B7: Lea Hofmann | C7: Logistik | D7: 28
A8: M04 | B8: Tim Schreiber | C8: Logistik | D8: 28
A9: M05 | B9: Mara Vogel | C9: Lager | D9: 26
A10: M06 | B10: Felix Krause | C10: Lager | D10: 26
A11: M07 | B11: Nina Albrecht | C11: Qualitaetssicherung | D11: 34
A12: M08 | B12: Paul Lehmann | C12: Qualitaetssicherung | D12: 34
A13: M09 | B13: Sara Engel | C13: Versand | D13: 27
A14: M10 | B14: David Kuhn | C14: Versand | D14: 27

Sheet Bestellungen
A1: Bewegungsdaten: Bestellungen Q1 2026
A2: Rohdaten ohne Formeln - dies ist die Bewegungstabelle, mit der in den Uebungssheets gearbeitet wird (SVERWEIS, XVERWEIS, FILTER usw. holen sich Werte aus dieser Tabelle und aus den Stammdaten).
A4: Bestell-ID | B4: Artikel-ID | C4: Bestelldatum | D4: Menge | E4: Mitarbeiter-ID | F4: Status | G4: Lieferzeit_Tage
A5: B001 | B5: A004 | C5: 46030 | D5: 12 | E5: M04 | F5: Geliefert | G5: 3
A6: B002 | B6: A004 | C6: 46096 | D6: 5 | E6: M10 | F6: Verzoegert | G6: 6
A7: B003 | B7: A001 | C7: 46040 | D7: 5 | E7: M01 | F7: Geliefert | G7: 3
A8: B004 | B8: A020 | C8: 46030 | D8: 30 | E8: M04 | F8: Storniert
A9: B005 | B9: A018 | C9: 46080 | D9: 10 | E9: M08 | F9: Offen
A10: B006 | B10: A009 | C10: 46027 | D10: 8 | E10: M07 | F10: Geliefert | G10: 4
A11: B007 | B11: A005 | C11: 46054 | D11: 15 | E11: M02 | F11: Geliefert | G11: 5
A12: B008 | B12: A004 | C12: 46072 | D12: 15 | E12: M10 | F12: Geliefert | G12: 2
A13: B009 | B13: A015 | C13: 46095 | D13: 5 | E13: M07 | F13: Geliefert | G13: 4
A14: B010 | B14: A020 | C14: 46073 | D14: 40 | E14: M04 | F14: Storniert
A15: B011 | B15: A003 | C15: 46032 | D15: 50 | E15: M04 | F15: Geliefert | G15: 2
A16: B012 | B16: A008 | C16: 46039 | D16: 20 | E16: M05 | F16: Verzoegert | G16: 11
A17: B013 | B17: A006 | C17: 46074 | D17: 15 | E17: M04 | F17: Storniert
A18: B014 | B18: A009 | C18: 46109 | D18: 5 | E18: M10 | F18: Storniert
A19: B015 | B19: A006 | C19: 46095 | D19: 10 | E19: M03 | F19: Verzoegert | G19: 12
A20: B016 | B20: A001 | C20: 46063 | D20: 10 | E20: M02 | F20: Verzoegert | G20: 9
A21: B017 | B21: A011 | C21: 46034 | D21: 10 | E21: M01 | F21: Geliefert | G21: 5
A22: B018 | B22: A009 | C22: 46035 | D22: 10 | E22: M10 | F22: Storniert
A23: B019 | B23: A011 | C23: 46054 | D23: 50 | E23: M08 | F23: Verzoegert | G23: 13
A24: B020 | B24: A005 | C24: 46060 | D24: 8 | E24: M04 | F24: Storniert
A25: B021 | B25: A018 | C25: 46095 | D25: 12 | E25: M10 | F25: Verzoegert | G25: 12
A26: B022 | B26: A012 | C26: 46055 | D26: 8 | E26: M09 | F26: Verzoegert | G26: 7
A27: B023 | B27: A002 | C27: 46041 | D27: 8 | E27: M03 | F27: Storniert
A28: B024 | B28: A014 | C28: 46103 | D28: 5 | E28: M07 | F28: Verzoegert | G28: 13
A29: B025 | B29: A017 | C29: 46059 | D29: 30 | E29: M01 | F29: Storniert
A30: B026 | B30: A004 | C30: 46095 | D30: 12 | E30: M06 | F30: Geliefert | G30: 4
A31: B027 | B31: A014 | C31: 46047 | D31: 25 | E31: M01 | F31: Storniert
A32: B028 | B32: A009 | C32: 46091 | D32: 8 | E32: M09 | F32: Geliefert | G32: 4
A33: B029 | B33: A017 | C33: 46104 | D33: 10 | E33: M03 | F33: Geliefert | G33: 3
A34: B030 | B34: A018 | C34: 46094 | D34: 2 | E34: M10 | F34: Geliefert | G34: 5
A35: B031 | B35: A001 | C35: 46041 | D35: 15 | E35: M05 | F35: Geliefert | G35: 2
A36: B032 | B36: A008 | C36: 46099 | D36: 5 | E36: M02 | F36: Storniert
A37: B033 | B37: A016 | C37: 46035 | D37: 30 | E37: M03 | F37: Geliefert | G37: 5
A38: B034 | B38: A001 | C38: 46103 | D38: 8 | E38: M01 | F38: Geliefert | G38: 4
A39: B035 | B39: A014 | C39: 46054 | D39: 30 | E39: M04 | F39: Storniert
A40: B036 | B40: A010 | C40: 46078 | D40: 50 | E40: M06 | F40: Verzoegert | G40: 14
A41: B037 | B41: A015 | C41: 46042 | D41: 10 | E41: M04 | F41: Geliefert | G41: 4
...

Sheet 01_SVERWEIS_WVERWEIS
A1: 01 | SVERWEIS und WVERWEIS
A2: Gruen hinterlegte Zellen zeigen eine fertige Beispielformel. Gelb hinterlegte Zellen (mit dem Symbol Uebung) sind fuer dich: trage dort deine eigene Formel ein. Die Loesungen findest du im Tabellenblatt 'Loesungen'.
A5: A) SVERWEIS - exakte Uebereinstimmung (Bereich_Verweis = FALSCH)
A6: Aufgabe: Hole aus den Artikel-Stammdaten Artikelname, Kategorie und Lieferant zur jeweiligen Artikel-ID. Spalte D ist komplett vorgeloest, Spalte E zeigt dir nur die erste Zeile, Spalte F ist komplett deine Uebung.
A8: Bestell-ID | B8: Artikel-ID | C8: Menge | D8: Artikelname (SVERWEIS) | E8: Kategorie (SVERWEIS) | F8: Lieferant (Uebung) | G8: Rabatt (Staffel-SVERWEIS) | I8: Mindestmenge | J8: Rabatt
A9: {='Bestellungen'!A5} -> B001 | B9: {='Bestellungen'!B5} -> A004 | C9: {='Bestellungen'!D5} -> 12 | D9: {=VLOOKUP($B9,'Stammdaten_Artikel'!$A$5:$F$24,2,FALSE())} -> Maus optisch | E9: {=VLOOKUP(B9,'Stammdaten_Artikel'!$A$5:$F$24,3,FALSE)} -> Elektronik | F9: {=VLOOKUP(B9,'Stammdaten_Artikel'!$A$5:$F$24,4,FALSE)} -> TechSupply GmbH | G9: {=VLOOKUP($C9,$I$9:$J$12,2,TRUE())} -> 0.05 | I9: 0 | J9: 0
A10: {='Bestellungen'!A6} -> B002 | B10: {='Bestellungen'!B6} -> A004 | C10: {='Bestellungen'!D6} -> 5 | D10: {=VLOOKUP($B10,'Stammdaten_Artikel'!$A$5:$F$24,2,FALSE())} -> Maus optisch | E10: {=VLOOKUP(B10,'Stammdaten_Artikel'!$A$5:$F$24,3,FALSE)} -> Elektronik | F10: {=VLOOKUP(B10,'Stammdaten_Artikel'!$A$5:$F$24,4,FALSE)} -> TechSupply GmbH | G10: {=VLOOKUP($C10,$I$9:$J$12,2,TRUE())} -> 0 | I10: 10 | J10: 0.05
A11: {='Bestellungen'!A7} -> B003 | B11: {='Bestellungen'!B7} -> A001 | C11: {='Bestellungen'!D7} -> 5 | D11: {=VLOOKUP($B11,'Stammdaten_Artikel'!$A$5:$F$24,2,FALSE())} -> Laptop 14 Zoll | E11: {=VLOOKUP(B11,'Stammdaten_Artikel'!$A$5:$F$24,3,FALSE)} -> Elektronik | F11: {=VLOOKUP(B11,'Stammdaten_Artikel'!$A$5:$F$24,4,FALSE)} -> TechSupply GmbH | G11: {=VLOOKUP($C11,$I$9:$J$12,2,TRUE())} -> 0 | I11: 25 | J11: 0.1
A12: {='Bestellungen'!A8} -> B004 | B12: {='Bestellungen'!B8} -> A020 | C12: {='Bestellungen'!D8} -> 30 | D12: {=VLOOKUP($B12,'Stammdaten_Artikel'!$A$5:$F$24,2,FALSE())} -> Webcam | E12: {=VLOOKUP(B12,'Stammdaten_Artikel'!$A$5:$F$24,3,FALSE)} -> Elektronik | F12: {=VLOOKUP(B12,'Stammdaten_Artikel'!$A$5:$F$24,4,FALSE)} -> TechSupply GmbH | G12: {=VLOOKUP($C12,$I$9:$J$12,2,TRUE())} -> 0.1 | I12: 40 | J12: 0.15
A13: {='Bestellungen'!A9} -> B005 | B13: {='Bestellungen'!B9} -> A018 | C13: {='Bestellungen'!D9} -> 10 | D13: {=VLOOKUP($B13,'Stammdaten_Artikel'!$A$5:$F$24,2,FALSE())} -> Luftpolsterfolie | E13: {=VLOOKUP(B13,'Stammdaten_Artikel'!$A$5:$F$24,3,FALSE)} -> Verpackung | F13: {=VLOOKUP(B13,'Stammdaten_Artikel'!$A$5:$F$24,4,FALSE)} -> PackIt GmbH | G13: {=VLOOKUP($C13,$I$9:$J$12,2,TRUE())} -> 0.05
A14: {='Bestellungen'!A10} -> B006 | B14: {='Bestellungen'!B10} -> A009 | C14: {='Bestellungen'!D10} -> 8 | D14: {=VLOOKUP($B14,'Stammdaten_Artikel'!$A$5:$F$24,2,FALSE())} -> Ordner A4 | E14: {=VLOOKUP(B14,'Stammdaten_Artikel'!$A$5:$F$24,3,FALSE)} -> Bueromaterial | F14: {=VLOOKUP(B14,'Stammdaten_Artikel'!$A$5:$F$24,4,FALSE)} -> PaperPlus KG | G14: {=VLOOKUP($C14,$I$9:$J$12,2,TRUE())} -> 0
A15: {='Bestellungen'!A11} -> B007 | B15: {='Bestellungen'!B11} -> A005 | C15: {='Bestellungen'!D11} -> 15 | D15: {=VLOOKUP($B15,'Stammdaten_Artikel'!$A$5:$F$24,2,FALSE())} -> USB-C Kabel | E15: {=VLOOKUP(B15,'Stammdaten_Artikel'!$A$5:$F$24,3,FALSE)} -> IT-Zubehoer | F15: {=VLOOKUP(B15,'Stammdaten_Artikel'!$A$5:$F$24,4,FALSE)} -> KabelPro AG | G15: {=VLOOKUP($C15,$I$9:$J$12,2,TRUE())} -> 0.05
A16: {='Bestellungen'!A12} -> B008 | B16: {='Bestellungen'!B12} -> A004 | C16: {='Bestellungen'!D12} -> 15 | D16: {=VLOOKUP($B16,'Stammdaten_Artikel'!$A$5:$F$24,2,FALSE())} -> Maus optisch | E16: {=VLOOKUP(B16,'Stammdaten_Artikel'!$A$5:$F$24,3,FALSE)} -> Elektronik | F16: {=VLOOKUP(B16,'Stammdaten_Artikel'!$A$5:$F$24,4,FALSE)} -> TechSupply GmbH | G16: {=VLOOKUP($C16,$I$9:$J$12,2,TRUE())} -> 0.05
A17: {='Bestellungen'!A13} -> B009 | B17: {='Bestellungen'!B13} -> A015 | C17: {='Bestellungen'!D13} -> 5 | D17: {=VLOOKUP($B17,'Stammdaten_Artikel'!$A$5:$F$24,2,FALSE())} -> Kartonbox klein | E17: {=VLOOKUP(B17,'Stammdaten_Artikel'!$A$5:$F$24,3,FALSE)} -> Verpackung | F17: {=VLOOKUP(B17,'Stammdaten_Artikel'!$A$5:$F$24,4,FALSE)} -> PackIt GmbH | G17: {=VLOOKUP($C17,$I$9:$J$12,2,TRUE())} -> 0
A18: {='Bestellungen'!A14} -> B010 | B18: {='Bestellungen'!B14} -> A020 | C18: {='Bestellungen'!D14} -> 40 | D18: {=VLOOKUP($B18,'Stammdaten_Artikel'!$A$5:$F$24,2,FALSE())} -> Webcam | E18: {=VLOOKUP(B18,'Stammdaten_Artikel'!$A$5:$F$24,3,FALSE)} -> Elektronik | F18: {=VLOOKUP(B18,'Stammdaten_Artikel'!$A$5:$F$24,4,FALSE)} -> TechSupply GmbH | G18: {=VLOOKUP($C18,$I$9:$J$12,2,TRUE())} -> 0.15
A19: {='Bestellungen'!A15} -> B011 | B19: {='Bestellungen'!B15} -> A003 | C19: {='Bestellungen'!D15} -> 50 | D19: {=VLOOKUP($B19,'Stammdaten_Artikel'!$A$5:$F$24,2,FALSE())} -> Tastatur kabellos | E19: {=VLOOKUP(B19,'Stammdaten_Artikel'!$A$5:$F$24,3,FALSE)} -> Elektronik | F19: {=VLOOKUP(B19,'Stammdaten_Artikel'!$A$5:$F$24,4,FALSE)} -> TechSupply GmbH | G19: {=VLOOKUP($C19,$I$9:$J$12,2,TRUE())} -> 0.15
A20: {='Bestellungen'!A16} -> B012 | B20: {='Bestellungen'!B16} -> A008 | C20: {='Bestellungen'!D16} -> 20 | D20: {=VLOOKUP($B20,'Stammdaten_Artikel'!$A$5:$F$24,2,FALSE())} -> Kugelschreiber | E20: {=VLOOKUP(B20,'Stammdaten_Artikel'!$A$5:$F$24,3,FALSE)} -> Bueromaterial | F20: {=VLOOKUP(B20,'Stammdaten_Artikel'!$A$5:$F$24,4,FALSE)} -> PaperPlus KG | G20: {=VLOOKUP($C20,$I$9:$J$12,2,TRUE())} -> 0.05
A21: {='Bestellungen'!A17} -> B013 | B21: {='Bestellungen'!B17} -> A006 | C21: {='Bestellungen'!D17} -> 15 | D21: {=VLOOKUP($B21,'Stammdaten_Artikel'!$A$5:$F$24,2,FALSE())} -> Headset | E21: {=VLOOKUP(B21,'Stammdaten_Artikel'!$A$5:$F$24,3,FALSE)} -> Elektronik | F21: {=VLOOKUP(B21,'Stammdaten_Artikel'!$A$5:$F$24,4,FALSE)} -> TechSupply GmbH | G21: {=VLOOKUP($C21,$I$9:$J$12,2,TRUE())} -> 0.05
A22: {='Bestellungen'!A18} -> B014 | B22: {='Bestellungen'!B18} -> A009 | C22: {='Bestellungen'!D18} -> 5 | D22: {=VLOOKUP($B22,'Stammdaten_Artikel'!$A$5:$F$24,2,FALSE())} -> Ordner A4 | E22: {=VLOOKUP(B22,'Stammdaten_Artikel'!$A$5:$F$24,3,FALSE)} -> Bueromaterial | F22: {=VLOOKUP(B22,'Stammdaten_Artikel'!$A$5:$F$24,4,FALSE)} -> PaperPlus KG | G22: {=VLOOKUP($C22,$I$9:$J$12,2,TRUE())} -> 0
A23: {='Bestellungen'!A19} -> B015 | B23: {='Bestellungen'!B19} -> A006 | C23: {='Bestellungen'!D19} -> 10 | D23: {=VLOOKUP($B23,'Stammdaten_Artikel'!$A$5:$F$24,2,FALSE())} -> Headset | E23: {=VLOOKUP(B23,'Stammdaten_Artikel'!$A$5:$F$24,3,FALSE)} -> Elektronik | F23: {=VLOOKUP(B23,'Stammdaten_Artikel'!$A$5:$F$24,4,FALSE)} -> TechSupply GmbH | G23: {=VLOOKUP($C23,$I$9:$J$12,2,TRUE())} -> 0.05
B24: A007 | E24: {=VLOOKUP(B24,'Stammdaten_Artikel'!$A$5:$F$24,3,FALSE)} -> Bueromaterial | F24: {=VLOOKUP(B24,'Stammdaten_Artikel'!$A$5:$F$24,4,FALSE)} -> PaperPlus KG | G24: {=VLOOKUP($C24,$I$9:$J$12,2,TRUE())} -> 0
B25: A008 | E25: {=VLOOKUP(B25,'Stammdaten_Artikel'!$A$5:$F$24,3,FALSE)} -> Bueromaterial | F25: {=VLOOKUP(B25,'Stammdaten_Artikel'!$A$5:$F$24,4,FALSE)} -> PaperPlus KG | G25: {=VLOOKUP($C25,$I$9:$J$12,2,TRUE())} -> 0
B26: A009 | E26: {=VLOOKUP(B26,'Stammdaten_Artikel'!$A$5:$F$24,3,FALSE)} -> Bueromaterial | F26: {=VLOOKUP(B26,'Stammdaten_Artikel'!$A$5:$F$24,4,FALSE)} -> PaperPlus KG | G26: {=VLOOKUP($C26,$I$9:$J$12,2,TRUE())} -> 0
B27: A010 | E27: {=VLOOKUP(B27,'Stammdaten_Artikel'!$A$5:$F$24,3,FALSE)} -> Bueromaterial | F27: {=VLOOKUP(B27,'Stammdaten_Artikel'!$A$5:$F$24,4,FALSE)} -> OfficeTech GmbH | G27: {=VLOOKUP($C27,$I$9:$J$12,2,TRUE())} -> 0
B28: A011 | E28: {=VLOOKUP(B28,'Stammdaten_Artikel'!$A$5:$F$24,3,FALSE)} -> Werkzeug | F28: {=VLOOKUP(B28,'Stammdaten_Artikel'!$A$5:$F$24,4,FALSE)} -> WerkzeugWelt AG | G28: {=VLOOKUP($C28,$I$9:$J$12,2,TRUE())} -> 0
B29: A012 | E29: {=VLOOKUP(B29,'Stammdaten_Artikel'!$A$5:$F$24,3,FALSE)} -> Werkzeug | F29: {=VLOOKUP(B29,'Stammdaten_Artikel'!$A$5:$F$24,4,FALSE)} -> WerkzeugWelt AG | G29: {=VLOOKUP($C29,$I$9:$J$12,2,TRUE())} -> 0
B30: A013 | E30: {=VLOOKUP(B30,'Stammdaten_Artikel'!$A$5:$F$24,3,FALSE)} -> Werkzeug | F30: {=VLOOKUP(B30,'Stammdaten_Artikel'!$A$5:$F$24,4,FALSE)} -> SafetyFirst GmbH | G30: {=VLOOKUP($C30,$I$9:$J$12,2,TRUE())} -> 0
B31: A014 | E31: {=VLOOKUP(B31,'Stammdaten_Artikel'!$A$5:$F$24,3,FALSE)} -> Werkzeug | F31: {=VLOOKUP(B31,'Stammdaten_Artikel'!$A$5:$F$24,4,FALSE)} -> SafetyFirst GmbH | G31: {=VLOOKUP($C31,$I$9:$J$12,2,TRUE())} -> 0
B32: A015 | E32: {=VLOOKUP(B32,'Stammdaten_Artikel'!$A$5:$F$24,3,FALSE)} -> Verpackung | F32: {=VLOOKUP(B32,'Stammdaten_Artikel'!$A$5:$F$24,4,FALSE)} -> PackIt GmbH | G32: {=VLOOKUP($C32,$I$9:$J$12,2,TRUE())} -> 0
B33: A016 | E33: {=VLOOKUP(B33,'Stammdaten_Artikel'!$A$5:$F$24,3,FALSE)} -> Verpackung | F33: {=VLOOKUP(B33,'Stammdaten_Artikel'!$A$5:$F$24,4,FALSE)} -> PackIt GmbH | G33: {=VLOOKUP($C33,$I$9:$J$12,2,TRUE())} -> 0
B34: A017 | E34: {=VLOOKUP(B34,'Stammdaten_Artikel'!$A$5:$F$24,3,FALSE)} -> Verpackung | F34: {=VLOOKUP(B34,'Stammdaten_Artikel'!$A$5:$F$24,4,FALSE)} -> PackIt GmbH | G34: {=VLOOKUP($C34,$I$9:$J$12,2,TRUE())} -> 0
B35: A018 | E35: {=VLOOKUP(B35,'Stammdaten_Artikel'!$A$5:$F$24,3,FALSE)} -> Verpackung | F35: {=VLOOKUP(B35,'Stammdaten_Artikel'!$A$5:$F$24,4,FALSE)} -> PackIt GmbH | G35: {=VLOOKUP($C35,$I$9:$J$12,2,TRUE())} -> 0
... B37: A020 | E37: {=VLOOKUP(B37,'Stammdaten_Artikel'!$A$5:$F$24,3,FALSE)} -> Elektronik | F37: {=VLOOKUP(B37,'Stammdaten_Artikel'!$A$5:$F$24,4,FALSE)} -> TechSupply GmbH | G37: {=VLOOKUP($C37,$I$9:$J$12,2,TRUE())} -> 0
A40: Spalte G zeigt SVERWEIS mit Bereich_Verweis=WAHR: die Mindestmenge-Tabelle rechts muss dafuer aufsteigend sortiert sein. Excel sucht den groessten Wert, der kleiner oder gleich der gesuchten Menge ist.
A41: $C9 : valeur à rechercher. $C signifie que la colonne C est bloquée si tu recopies la formule horizontalement
A42: $I$9:$J$12 : tableau dans lequel Excel effectue la recherche. La recherche se fait uniquement dans la première colonne, donc I9:I12. $ bloque les lignes et les colonnes lors d'une copie de la formule.
A43: 2 : Excel retourne le résultat de la 2ᵉ colonne du tableau, donc J9:J12.
A45: WAHR() : signifie VRAI en allemand. Cela demande une recherche approximative. La première colonne I9:I12 doit donc être triée dans l'ordre croissant.
A50: B) WVERWEIS - horizontale Suche
A51: Aufgabe: Die Quartalswerte stehen in einer Kopfzeile (Q1-Q4). WVERWEIS sucht in dieser Zeile und liefert den Wert aus der angegebenen Zeile der Tabelle zurueck.
...

Sheet 02_INDEX_VERGLEICH
A1: 02 | INDEX und VERGLEICH
A2: INDEX/VERGLEICH ist flexibler als SVERWEIS: die Suchspalte muss nicht die erste Spalte der Matrix sein. Gruen = fertige Beispielformel, Gelb = deine Uebung.
A5: A) INDEX/VERGLEICH als SVERWEIS-Ersatz
A6: Gleiche Aufgabe wie in Blatt 01, jetzt mit INDEX/VERGLEICH geloest. Spalte D ist vorgeloest, Spalte E ist deine Uebung (nur Zeile 1 ist als Beispiel geloest).
A8: Bestell-ID | B8: Artikel-ID | C8: Menge | D8: Artikelname (INDEX/VERGLEICH) | E8: Kategorie (Uebung)
A9: {='Bestellungen'!A5} -> B001 | B9: {='Bestellungen'!B5} -> A004 | C9: {='Bestellungen'!D5} -> 12 | D9: {=INDEX('Stammdaten_Artikel'!$B$5:$B$24,MATCH($B9,'Stammdaten_Artikel'!$A$5:$A$24,0))} -> Maus optisch | E9: {=INDEX('Stammdaten_Artikel'!$C$5:$C$24,MATCH(B9,'Stammdaten_Artikel'!$A$5:$A$24,0))} -> Elektronik
A10: {='Bestellungen'!A6} -> B002 | B10: {='Bestellungen'!B6} -> A004 | C10: {='Bestellungen'!D6} -> 5 | D10: {=INDEX('Stammdaten_Artikel'!$B$5:$B$24,MATCH($B10,'Stammdaten_Artikel'!$A$5:$A$24,0))} -> Maus optisch | E10: {=INDEX('Stammdaten_Artikel'!$C$5:$C$24,MATCH(B10,'Stammdaten_Artikel'!$A$5:$A$24,0))} -> Elektronik
A11: {='Bestellungen'!A7} -> B003 | B11: {='Bestellungen'!B7} -> A001 | C11: {='Bestellungen'!D7} -> 5 | D11: {=INDEX('Stammdaten_Artikel'!$B$5:$B$24,MATCH($B11,'Stammdaten_Artikel'!$A$5:$A$24,0))} -> Laptop 14 Zoll | E11: {=INDEX('Stammdaten_Artikel'!$C$5:$C$24,MATCH(B11,'Stammdaten_Artikel'!$A$5:$A$24,0))} -> Elektronik
A12: {='Bestellungen'!A8} -> B004 | B12: {='Bestellungen'!B8} -> A020 | C12: {='Bestellungen'!D8} -> 30 | D12: {=INDEX('Stammdaten_Artikel'!$B$5:$B$24,MATCH($B12,'Stammdaten_Artikel'!$A$5:$A$24,0))} -> Webcam | E12: {=INDEX('Stammdaten_Artikel'!$C$5:$C$24,MATCH(B12,'Stammdaten_Artikel'!$A$5:$A$24,0))} -> Elektronik
A13: {='Bestellungen'!A9} -> B005 | B13: {='Bestellungen'!B9} -> A018 | C13: {='Bestellungen'!D9} -> 10 | D13: {=INDEX('Stammdaten_Artikel'!$B$5:$B$24,MATCH($B13,'Stammdaten_Artikel'!$A$5:$A$24,0))} -> Luftpolsterfolie | E13: {=INDEX('Stammdaten_Artikel'!$C$5:$C$24,MATCH(B13,'Stammdaten_Artikel'!$A$5:$A$24,0))} -> Verpackung
A14: {='Bestellungen'!A10} -> B006 | B14: {='Bestellungen'!B10} -> A009 | C14: {='Bestellungen'!D10} -> 8 | D14: {=INDEX('Stammdaten_Artikel'!$B$5:$B$24,MATCH($B14,'Stammdaten_Artikel'!$A$5:$A$24,0))} -> Ordner A4 | E14: {=INDEX('Stammdaten_Artikel'!$C$5:$C$24,MATCH(B14,'Stammdaten_Artikel'!$A$5:$A$24,0))} -> Bueromaterial
A15: {='Bestellungen'!A11} -> B007 | B15: {='Bestellungen'!B11} -> A005 | C15: {='Bestellungen'!D11} -> 15 | D15: {=INDEX('Stammdaten_Artikel'!$B$5:$B$24,MATCH($B15,'Stammdaten_Artikel'!$A$5:$A$24,0))} -> USB-C Kabel | E15: {=INDEX('Stammdaten_Artikel'!$C$5:$C$24,MATCH(B15,'Stammdaten_Artikel'!$A$5:$A$24,0))} -> IT-Zubehoer
A16: {='Bestellungen'!A12} -> B008 | B16: {='Bestellungen'!B12} -> A004 | C16: {='Bestellungen'!D12} -> 15 | D16: {=INDEX('Stammdaten_Artikel'!$B$5:$B$24,MATCH($B16,'Stammdaten_Artikel'!$A$5:$A$24,0))} -> Maus optisch | E16: {=INDEX('Stammdaten_Artikel'!$C$5:$C$24,MATCH(B16,'Stammdaten_Artikel'!$A$5:$A$24,0))} -> Elektronik
A17: {='Bestellungen'!A13} -> B009 | B17: {='Bestellungen'!B13} -> A015 | C17: {='Bestellungen'!D13} -> 5 | D17: {=INDEX('Stammdaten_Artikel'!$B$5:$B$24,MATCH($B17,'Stammdaten_Artikel'!$A$5:$A$24,0))} -> Kartonbox klein | E17: {=INDEX('Stammdaten_Artikel'!$C$5:$C$24,MATCH(B17,'Stammdaten_Artikel'!$A$5:$A$24,0))} -> Verpackung
A18: {='Bestellungen'!A14} -> B010 | B18: {='Bestellungen'!B14} -> A020 | C18: {='Bestellungen'!D14} -> 40 | D18: {=INDEX('Stammdaten_Artikel'!$B$5:$B$24,MATCH($B18,'Stammdaten_Artikel'!$A$5:$A$24,0))} -> Webcam | E18: {=INDEX('Stammdaten_Artikel'!$C$5:$C$24,MATCH(B18,'Stammdaten_Artikel'!$A$5:$A$24,0))} -> Elektronik
A19: {='Bestellungen'!A15} -> B011 | B19: {='Bestellungen'!B15} -> A003 | C19: {='Bestellungen'!D15} -> 50 | D19: {=INDEX('Stammdaten_Artikel'!$B$5:$B$24,MATCH($B19,'Stammdaten_Artikel'!$A$5:$A$24,0))} -> Tastatur kabellos | E19: {=INDEX('Stammdaten_Artikel'!$C$5:$C$24,MATCH(B19,'Stammdaten_Artikel'!$A$5:$A$24,0))} -> Elektronik
A20: {='Bestellungen'!A16} -> B012 | B20: {='Bestellungen'!B16} -> A008 | C20: {='Bestellungen'!D16} -> 20 | D20: {=INDEX('Stammdaten_Artikel'!$B$5:$B$24,MATCH($B20,'Stammdaten_Artikel'!$A$5:$A$24,0))} -> Kugelschreiber | E20: {=INDEX('Stammdaten_Artikel'!$C$5:$C$24,MATCH(B20,'Stammdaten_Artikel'!$A$5:$A$24,0))} -> Bueromaterial
... A23: {='Bestellungen'!A19} -> B015 | B23: {='Bestellungen'!B19} -> A006 | C23: {='Bestellungen'!D19} -> 10 | D23: {=INDEX('Stammdaten_Artikel'!$B$5:$B$24,MATCH($B23,'Stammdaten_Artikel'!$A$5:$A$24,0))} -> Headset | E23: {=INDEX('Stammdaten_Artikel'!$C$5:$C$24,MATCH(B23,'Stammdaten_Artikel'!$A$5:$A$24,0))} -> Elektronik
A28: B) Suche nach links - die eigentliche Staerke von INDEX/VERGLEICH
A29: In den Stammdaten steht die Artikel-ID (Spalte A) LINKS vom Artikelnamen (Spalte B). SVERWEIS kann das nicht direkt loesen, weil es immer nur nach rechts sucht. INDEX/VERGLEICH ist egal, in welche Richtung gesucht wird.
A31: Artikelname (Eingabe): | C31: Schraubendreher-Set
A32: Gefundene Artikel-ID (INDEX/VERGLEICH): | C32: {=INDEX('Stammdaten_Artikel'!$A$5:$A$24,MATCH(C31,'Stammdaten_Artikel'!$B$5:$B$24,0))} -> A012
A35: Artikelname (Eingabe): | C35: Bohrmaschine
A36: Uebung: Lieferant finden (INDEX/VERGLEICH, Spalte D im Stamm): | C36: Uebung: INDEX/VERGLEICH schreiben

Sheet 03_XVERWEIS_XVERGLEICH
A1: 03 | XVERWEIS und XVERGLEICH
A2: XVERWEIS ist der moderne Nachfolger von SVERWEIS/WVERWEIS/INDEX-VERGLEICH (ab Excel 365). Gruen = fertige Beispielformel, Gelb = deine Uebung.
A5: A) XVERWEIS - Suche nach links ohne Spaltenzaehlen
A6: Syntax: =XVERWEIS(Suchkriterium; Suchmatrix; Rueckgabematrix; ...). Anders als bei INDEX/VERGLEICH gibst du Such- und Rueckgabebereich direkt an - keine Positionsberechnung noetig.
A8: Artikelname (Eingabe): | C8: Schraubendreher-Set
A9: Gefundene Artikel-ID (XVERWEIS): | C9: {=_xlfn.XLOOKUP(C8,'Stammdaten_Artikel'!$B$5:$B$24,'Stammdaten_Artikel'!$A$5:$A$24)} -> A012
A12: Artikelname (Eingabe): | C12: Aktenvernichter
A13: Uebung: Kategorie finden (XVERWEIS): | C13: Uebung: XVERWEIS schreiben
A16: B) Der Parameter wenn_nicht_gefunden
A17: Klassisches SVERWEIS liefert bei einem nicht vorhandenen Suchkriterium den Fehler #NV. XVERWEIS kann stattdessen direkt einen eigenen Text zurueckgeben.
A19: Artikel-ID (Eingabe, existiert NICHT): | C19: A099
A20: Ergebnis mit wenn_nicht_gefunden: | C20: {=_xlfn.XLOOKUP(C19,'Stammdaten_Artikel'!$A$5:$A$24,'Stammdaten_Artikel'!$B$5:$B$24,"Artikel nicht im Stamm gefunden")} -> Artikel nicht im Stamm gefunden
A23: C) Suchmodus -1: von unten nach oben suchen
A24: Bei Prozessdaten steht der zeitlich juengste Eintrag oft weiter unten in der Tabelle. Suchmodus -1 durchsucht die Matrix von unten nach oben und liefert den ERSTEN Treffer von unten - also den letzten Vorgang zu einer Artikel-ID.
A26: Artikel-ID (Eingabe): | C26: A001
A27: Status der letzten Bestellung (XVERWEIS, Suchmodus -1): | C27: {=_xlfn.XLOOKUP(C26,'Bestellungen'!$B$5:$B$44,'Bestellungen'!$F$5:$F$44,"keine Bestellung gefunden",0,-1)} -> Offen
A30: Artikel-ID (Eingabe): | C30: A007
A31: Uebung: Lieferzeit_Tage der letzten Bestellung (Suchmodus -1): | C31: Uebung: XVERWEIS mit Suchmodus -1 schreiben
A34: XVERWEIS(C8;Stammdaten_Artikel::Tabelle 1::$B$5:$B$24;Stammdaten_Artikel::Tabelle 1::$A$5:$A$24)
A35: Cherche la valeur de C8 dans la colonne B de la feuille/table Stammdaten_Artikel, et renvoie la valeur correspondante de la colonne A.
A36: 8 → la valeur recherchée. Stammdaten_Artikel::Tabelle 1::$B$5:$B$24 → la colonne dans laquelle Excel cherche. Ici : B5:B24. Stammdaten_Artikel::Tabelle 1::$A$5:$A$24 → la colonne dont Excel renvoie le résultat. Ici : A5:A24.

Sheet 04_Dynamische_Arrays
A1: 04 | Dynamische Array-Funktionen
A2: EINDEUTIG, FILTER, SORTIEREN und SEQUENZ liefern automatisch ein Array zurueck, das sich ueber mehrere Zellen verteilt (Spill-Bereich). Du gibst die Formel nur in die erste Zelle ein - die Zellen darunter/daneben muessen leer bleiben.
A5: A) EINDEUTIG
A6: EINDEUTIG entfernt Duplikate aus einer Liste, ohne die Originaldaten zu veraendern.
C7: Kategorien (EINDEUTIG) | F7: Status-Werte (EINDEUTIG)
A17: B) FILTER
A18: FILTER gibt nur die Zeilen zurueck, die eine Bedingung erfuellen - hier alle Bestellungen mit Status 'Verzoegert'.
A20: Bestell-ID | B20: Artikel-ID | C20: Bestelldatum | D20: Menge | E20: Mitarbeiter-ID | F20: Status | G20: Lieferzeit_Tage
A21: {=_xlfn.FILTER('Bestellungen'!$A$5:$G$44,'Bestellungen'!$F$5:$F$44="Verzoegert")} -> B002 | B21: A004 | C21: 46096 | D21: 5 | E21: M10 | F21: Verzoegert | G21: 6
A22: B012 | B22: A008 | C22: 46039 | D22: 20 | E22: M05 | F22: Verzoegert | G22: 11
A23: B015 | B23: A006 | C23: 46095 | D23: 10 | E23: M03 | F23: Verzoegert | G23: 12
A24: B016 | B24: A001 | C24: 46063 | D24: 10 | E24: M02 | F24: Verzoegert | G24: 9
A25: B019 | B25: A011 | C25: 46054 | D25: 50 | E25: M08 | F25: Verzoegert | G25: 13
A26: B021 | B26: A018 | C26: 46095 | D26: 12 | E26: M10 | F26: Verzoegert | G26: 12
A27: B022 | B27: A012 | C27: 46055 | D27: 8 | E27: M09 | F27: Verzoegert | G27: 7
A28: B024 | B28: A014 | C28: 46103 | D28: 5 | E28: M07 | F28: Verzoegert | G28: 13
A29: B036 | B29: A010 | C29: 46078 | D29: 50 | E29: M06 | F29: Verzoegert | G29: 14
A31: Uebung: Schreibe in der Zelle darunter eine FILTER-Formel, die alle Bestellungen mit Menge > 30 zurueckgibt (Bereich Bestellungen!A:G, Bedingung auf Spalte D).
A32: Uebung: FILTER-Formel hier eintragen
A35: C) SORTIEREN kombiniert mit FILTER
A36: Funktionen lassen sich verschachteln: zuerst filtern, das Ergebnis direkt weiter sortieren - hier nach Lieferzeit_Tage absteigend, um die groessten Verzoegerungen oben zu sehen.
A38: Bestell-ID | B38: Artikel-ID | C38: Bestelldatum | D38: Menge | E38: Mitarbeiter-ID | F38: Status | G38: Lieferzeit_Tage
A39: {=_xlfn.SORT(_xlfn.FILTER('Bestellungen'!$A$5:$G$44,'Bestellungen'!$F$5:$F$44="Verzoegert"),7,-1)} -> B036 | B39: A010 | C39: 46078 | D39: 50 | E39: M06 | F39: Verzoegert | G39: 14
A40: B019 | B40: A011 | C40: 46054 | D40: 50 | E40: M08 | F40: Verzoegert | G40: 13
A41: B024 | B41: A014 | C41: 46103 | D41: 5 | E41: M07 | F41: Verzoegert | G41: 13
A42: B015 | B42: A006 | C42: 46095 | D42: 10 | E42: M03 | F42: Verzoegert | G42: 12
A43: B021 | B43: A018 | C43: 46095 | D43: 12 | E43: M10 | F43: Verzoegert | G43: 12
A44: B012 | B44: A008 | C44: 46039 | D44: 20 | E44: M05 | F44: Verzoegert | G44: 11
A45: B016 | B45: A001 | C45: 46063 | D45: 10 | E45: M02 | F45: Verzoegert | G45: 9
A46: B022 | B46: A012 | C46: 46055 | D46: 8 | E46: M09 | F46: Verzoegert | G46: 7
A47: B002 | B47: A004 | C47: 46096 | D47: 5 | E47: M10 | F47: Verzoegert | G47: 6
A51: D) SEQUENZ
A52: SEQUENZ erzeugt eine Zahlenreihe. Kombiniert mit DATUM und TEXT lassen sich z.B. automatisch 12 Monatsnamen fuer eine Jahresuebersicht erzeugen, ohne sie einzeln zu tippen.
A54: Monatsnummern (SEQUENZ) | D54: Monatsnamen 2026 (SEQUENZ + DATUM + TEXT)

Sheet Loesungen
A1: Loesungen zu den Uebungszellen
A2: Schau hier erst nach, wenn du es selbst versucht hast. Die Formeln sind als Text hinterlegt (sie rechnen hier nicht), damit du sie in Ruhe lesen und danach selbst eintippen kannst.
A4: Nr. | B4: Tabellenblatt | C4: Zelle | D4: Aufgabe | E4: Loesungsformel
A5: 1 | B5: 01_SVERWEIS_WVERWEIS | C5: E10:E23 | D5: Kategorie per SVERWEIS | E5: =SVERWEIS($B10;Stammdaten_Artikel!$A$5:$F$24;3;FALSCH)
A6: 2 | B6: 01_SVERWEIS_WVERWEIS | C6: F9:F23 | D6: Lieferant per SVERWEIS | E6: =SVERWEIS($B9;Stammdaten_Artikel!$A$5:$F$24;4;FALSCH)
A7: 3 | B7: 01_SVERWEIS_WVERWEIS | C7: C37 | D7: Gewinn in Q4 per WVERWEIS | E7: =WVERWEIS("Q4";$A$31:$E$34;4;FALSCH)
A8: 4 | B8: 01_SVERWEIS_WVERWEIS | C8: C38 | D8: Umsatz in Q1 per WVERWEIS | E8: =WVERWEIS("Q1";$A$31:$E$34;2;FALSCH)
A9: 5 | B9: 02_INDEX_VERGLEICH | C9: E10:E23 | D9: Kategorie per INDEX/VERGLEICH | E9: =INDEX(Stammdaten_Artikel!$C$5:$C$24;VERGLEICH($B10;Stammdaten_Artikel!$A$5:$A$24;0))
A10: 6 | B10: 02_INDEX_VERGLEICH | C10: C34 | D10: Lieferant zu 'Bohrmaschine' per INDEX/VERGLEICH (Suche nach links) | E10: =INDEX(Stammdaten_Artikel!$D$5:$D$24;VERGLEICH(C33;Stammdaten_Artikel!$B$5:$B$24;0))
A11: 7 | B11: 03_XVERWEIS_XVERGLEICH | C11: C13 | D11: Kategorie zu 'Aktenvernichter' per XVERWEIS | E11: =XVERWEIS(C12;Stammdaten_Artikel!$B$5:$B$24;Stammdaten_Artikel!$C$5:$C$24)
A12: 8 | B12: 03_XVERWEIS_XVERGLEICH | C12: C31 | D12: Lieferzeit_Tage der letzten Bestellung zu A007 (Suchmodus -1) | E12: =XVERWEIS(C30;Bestellungen!$B$5:$B$44;Bestellungen!$G$5:$G$44;"keine Bestellung gefunden";0;-1)
A13: 9 | B13: 04_Dynamische_Arrays | C13: Uebungszelle unter dem FILTER-Beispiel | D13: Bestellungen mit Menge > 30 per FILTER | E13: =FILTER(Bestellungen!$A$5:$G$44;Bestellungen!$D$5:$D$44>30)
