Workbook

Sheet Export-Zusammenfassung
B3: Dieses Dokument wurde aus Numbers exportiert und jede Tabelle in ein Excel-Arbeitsblatt umgewandelt. Alle anderen Objekte der einzelnen Numbers-Blätter wurden auf eigene Arbeitsblätter übertragen. Beachte, dass die Formelberechnungen in Excel möglicherweise anders sind.
B7: Name des Numbers-Blatts | C7: Numbers-Tabellenname | D7: Name des Excel-Arbeitsblatts
B9: Stammdaten_Artikel
C10: Tabelle 1 | D10: Stammdaten_Artikel
B11: Stammdaten_Mitarbeiter
C12: Tabelle 1 | D12: Stammdaten_Mitarbeiter
B13: Bestellungen
C14: Tabelle 1 | D14: Bestellungen
B15: 01_SVERWEIS_WVERWEIS
C16: Tabelle 1 | D16: 01_SVERWEIS_WVERWEIS
B17: 02_INDEX_VERGLEICH
C18: Tabelle 1 | D18: 02_INDEX_VERGLEICH
B19: 03_XVERWEIS_XVERGLEICH
C20: Tabelle 1 | D20: 03_XVERWEIS_XVERGLEICH

Sheet Stammdaten_Artikel
A1: Stammdaten: Artikel
A3: Artikel-ID | B3: Artikelname | C3: Kategorie | D3: Lieferant | E3: Einkaufspreis (EUR) | F3: Lagerort
A4: A001 | B4: Laptop 14 Zoll | C4: Elektronik | D4: TechSupply GmbH | E4: 650 | F4: Lager A1
A5: A002 | B5: Monitor 24 Zoll | C5: Elektronik | D5: TechSupply GmbH | E5: 180 | F5: Lager A1
A6: A003 | B6: Tastatur kabellos | C6: Elektronik | D6: TechSupply GmbH | E6: 35 | F6: Lager A1
A7: A004 | B7: Maus optisch | C7: Elektronik | D7: TechSupply GmbH | E7: 18 | F7: Lager A1
A8: A005 | B8: USB-C Kabel | C8: IT-Zubehoer | D8: KabelPro AG | E8: 8 | F8: Lager A2
A9: A006 | B9: Headset | C9: Elektronik | D9: TechSupply GmbH | E9: 45 | F9: Lager A1
A10: A007 | B10: Druckerpapier A4 | C10: Bueromaterial | D10: PaperPlus KG | E10: 6 | F10: Lager B1
A11: A008 | B11: Kugelschreiber | C11: Bueromaterial | D11: PaperPlus KG | E11: 1 | F11: Lager B1
A12: A009 | B12: Ordner A4 | C12: Bueromaterial | D12: PaperPlus KG | E12: 2 | F12: Lager B1
A13: A010 | B13: Aktenvernichter | C13: Bueromaterial | D13: OfficeTech GmbH | E13: 120 | F13: Lager B2
A14: A011 | B14: Bohrmaschine | C14: Werkzeug | D14: WerkzeugWelt AG | E14: 95 | F14: Lager C1
A15: A012 | B15: Schraubendreher-Set | C15: Werkzeug | D15: WerkzeugWelt AG | E15: 25 | F15: Lager C1
... A23: A020 | B23: Webcam | C23: Elektronik | D23: TechSupply GmbH | E23: 55 | F23: Lager A1

Sheet Stammdaten_Mitarbeiter
A1: Stammdaten: Mitarbeiter
A3: Mitarbeiter-ID | B3: Name | C3: Abteilung | D3: Stundensatz (EUR)
A4: M01 | B4: Anna Berger | C4: Einkauf | D4: 32
A5: M02 | B5: Jonas Wolf | C5: Einkauf | D5: 32
A6: M03 | B6: Lea Hofmann | C6: Logistik | D6: 28
A7: M04 | B7: Tim Schreiber | C7: Logistik | D7: 28
A8: M05 | B8: Mara Vogel | C8: Lager | D8: 26
A9: M06 | B9: Felix Krause | C9: Lager | D9: 26
A10: M07 | B10: Nina Albrecht | C10: Qualitaetssicherung | D10: 34
A11: M08 | B11: Paul Lehmann | C11: Qualitaetssicherung | D11: 34
A12: M09 | B12: Sara Engel | C12: Versand | D12: 27
A13: M10 | B13: David Kuhn | C13: Versand | D13: 27

Sheet Bestellungen
A1: Bewegungsdaten: Bestellungen Q1 2026
A3: Bestell-ID | B3: Artikel-ID | C3: Bestelldatum | D3: Menge | E3: Mitarbeiter-ID | F3: Status | G3: Lieferzeit_Tage
A4: B001 | B4: A004 | C4: 46030 | D4: 12 | E4: M04 | F4: Geliefert | G4: 3
A5: B002 | B5: A004 | C5: 46096 | D5: 5 | E5: M10 | F5: Verzoegert | G5: 6
A6: B003 | B6: A001 | C6: 46040 | D6: 5 | E6: M01 | F6: Geliefert | G6: 3
A7: B004 | B7: A020 | C7: 46030 | D7: 30 | E7: M04 | F7: Storniert
A8: B005 | B8: A018 | C8: 46080 | D8: 10 | E8: M08 | F8: Offen
A9: B006 | B9: A009 | C9: 46027 | D9: 8 | E9: M07 | F9: Geliefert | G9: 4
A10: B007 | B10: A005 | C10: 46054 | D10: 15 | E10: M02 | F10: Geliefert | G10: 5
A11: B008 | B11: A004 | C11: 46072 | D11: 15 | E11: M10 | F11: Geliefert | G11: 2
A12: B009 | B12: A015 | C12: 46095 | D12: 5 | E12: M07 | F12: Geliefert | G12: 4
A13: B010 | B13: A020 | C13: 46073 | D13: 40 | E13: M04 | F13: Storniert
A14: B011 | B14: A003 | C14: 46032 | D14: 50 | E14: M04 | F14: Geliefert | G14: 2
A15: B012 | B15: A008 | C15: 46039 | D15: 20 | E15: M05 | F15: Verzoegert | G15: 11
A16: B013 | B16: A006 | C16: 46074 | D16: 15 | E16: M04 | F16: Storniert
A17: B014 | B17: A009 | C17: 46109 | D17: 5 | E17: M10 | F17: Storniert
A18: B015 | B18: A006 | C18: 46095 | D18: 10 | E18: M03 | F18: Verzoegert | G18: 12
A19: B016 | B19: A001 | C19: 46063 | D19: 10 | E19: M02 | F19: Verzoegert | G19: 9
A20: B017 | B20: A011 | C20: 46034 | D20: 10 | E20: M01 | F20: Geliefert | G20: 5
A21: B018 | B21: A009 | C21: 46035 | D21: 10 | E21: M10 | F21: Storniert
A22: B019 | B22: A011 | C22: 46054 | D22: 50 | E22: M08 | F22: Verzoegert | G22: 13
A23: B020 | B23: A005 | C23: 46060 | D23: 8 | E23: M04 | F23: Storniert
A24: B021 | B24: A018 | C24: 46095 | D24: 12 | E24: M10 | F24: Verzoegert | G24: 12
A25: B022 | B25: A012 | C25: 46055 | D25: 8 | E25: M09 | F25: Verzoegert | G25: 7
A26: B023 | B26: A002 | C26: 46041 | D26: 8 | E26: M03 | F26: Storniert
A27: B024 | B27: A014 | C27: 46103 | D27: 5 | E27: M07 | F27: Verzoegert | G27: 13
A28: B025 | B28: A017 | C28: 46059 | D28: 30 | E28: M01 | F28: Storniert
A29: B026 | B29: A004 | C29: 46095 | D29: 12 | E29: M06 | F29: Geliefert | G29: 4
A30: B027 | B30: A014 | C30: 46047 | D30: 25 | E30: M01 | F30: Storniert
A31: B028 | B31: A009 | C31: 46091 | D31: 8 | E31: M09 | F31: Geliefert | G31: 4
A32: B029 | B32: A017 | C32: 46104 | D32: 10 | E32: M03 | F32: Geliefert | G32: 3
A33: B030 | B33: A018 | C33: 46094 | D33: 2 | E33: M10 | F33: Geliefert | G33: 5
A34: B031 | B34: A001 | C34: 46041 | D34: 15 | E34: M05 | F34: Geliefert | G34: 2
A35: B032 | B35: A008 | C35: 46099 | D35: 5 | E35: M02 | F35: Storniert
A36: B033 | B36: A016 | C36: 46035 | D36: 30 | E36: M03 | F36: Geliefert | G36: 5
A37: B034 | B37: A001 | C37: 46103 | D37: 8 | E37: M01 | F37: Geliefert | G37: 4
A38: B035 | B38: A014 | C38: 46054 | D38: 30 | E38: M04 | F38: Storniert
A39: B036 | B39: A010 | C39: 46078 | D39: 50 | E39: M06 | F39: Verzoegert | G39: 14
A40: B037 | B40: A015 | C40: 46042 | D40: 10 | E40: M04 | F40: Geliefert | G40: 4
A41: B038 | B41: A001 | C41: 46102 | D41: 30 | E41: M04 | F41: Offen
...

Sheet 01_SVERWEIS_WVERWEIS
A1: 01 | SVERWEIS und WVERWEIS
A3: A) SVERWEIS - exakte Uebereinstimmung (Bereich_Verweis = FALSCH)
A5: Bestell-ID | B5: Artikel-ID | C5: Menge | D5: Artikelname (SVERWEIS) | E5: Kategorie (SVERWEIS) | F5: Lieferant (Uebung) | G5: Rabatt (Staffel-SVERWEIS) | I5: Mindestmenge | J5: Rabatt
A6: {='Bestellungen'!A4} -> B001 | B6: {='Bestellungen'!B4} -> A004 | C6: {='Bestellungen'!D4} -> 12 | D6: {=VLOOKUP($B6,'Stammdaten_Artikel'!$A$4:$F$23,2,FALSE())} -> Maus optisch | E6: {=VLOOKUP(B6,'Stammdaten_Artikel'!$A$4:$F$23,3,FALSE)} -> Elektronik | F6: {=VLOOKUP(B6,'Stammdaten_Artikel'!$A$4:$F$23,4,FALSE)} -> TechSupply GmbH | G6: {=VLOOKUP($C6,$I$6:$J$9,2,TRUE())} -> 0.05 | I6: 0 | J6: 0
A7: {='Bestellungen'!A5} -> B002 | B7: {='Bestellungen'!B5} -> A004 | C7: {='Bestellungen'!D5} -> 5 | D7: {=VLOOKUP($B7,'Stammdaten_Artikel'!$A$4:$F$23,2,FALSE())} -> Maus optisch | E7: {=VLOOKUP(B7,'Stammdaten_Artikel'!$A$4:$F$23,3,FALSE)} -> Elektronik | F7: {=VLOOKUP(B7,'Stammdaten_Artikel'!$A$4:$F$23,4,FALSE)} -> TechSupply GmbH | G7: {=VLOOKUP($C7,$I$6:$J$9,2,TRUE())} -> 0 | I7: 10 | J7: 0.05
A8: {='Bestellungen'!A6} -> B003 | B8: {='Bestellungen'!B6} -> A001 | C8: {='Bestellungen'!D6} -> 5 | D8: {=VLOOKUP($B8,'Stammdaten_Artikel'!$A$4:$F$23,2,FALSE())} -> Laptop 14 Zoll | E8: {=VLOOKUP(B8,'Stammdaten_Artikel'!$A$4:$F$23,3,FALSE)} -> Elektronik | F8: {=VLOOKUP(B8,'Stammdaten_Artikel'!$A$4:$F$23,4,FALSE)} -> TechSupply GmbH | G8: {=VLOOKUP($C8,$I$6:$J$9,2,TRUE())} -> 0 | I8: 25 | J8: 0.1
A9: {='Bestellungen'!A7} -> B004 | B9: {='Bestellungen'!B7} -> A020 | C9: {='Bestellungen'!D7} -> 30 | D9: {=VLOOKUP($B9,'Stammdaten_Artikel'!$A$4:$F$23,2,FALSE())} -> Webcam | E9: {=VLOOKUP(B9,'Stammdaten_Artikel'!$A$4:$F$23,3,FALSE)} -> Elektronik | F9: {=VLOOKUP(B9,'Stammdaten_Artikel'!$A$4:$F$23,4,FALSE)} -> TechSupply GmbH | G9: {=VLOOKUP($C9,$I$6:$J$9,2,TRUE())} -> 0.1 | I9: 40 | J9: 0.15
A10: {='Bestellungen'!A8} -> B005 | B10: {='Bestellungen'!B8} -> A018 | C10: {='Bestellungen'!D8} -> 10 | D10: {=VLOOKUP($B10,'Stammdaten_Artikel'!$A$4:$F$23,2,FALSE())} -> Luftpolsterfolie | E10: {=VLOOKUP(B10,'Stammdaten_Artikel'!$A$4:$F$23,3,FALSE)} -> Verpackung | F10: {=VLOOKUP(B10,'Stammdaten_Artikel'!$A$4:$F$23,4,FALSE)} -> PackIt GmbH | G10: {=VLOOKUP($C10,$I$6:$J$9,2,TRUE())} -> 0.05
A11: {='Bestellungen'!A9} -> B006 | B11: {='Bestellungen'!B9} -> A009 | C11: {='Bestellungen'!D9} -> 8 | D11: {=VLOOKUP($B11,'Stammdaten_Artikel'!$A$4:$F$23,2,FALSE())} -> Ordner A4 | E11: {=VLOOKUP(B11,'Stammdaten_Artikel'!$A$4:$F$23,3,FALSE)} -> Bueromaterial | F11: {=VLOOKUP(B11,'Stammdaten_Artikel'!$A$4:$F$23,4,FALSE)} -> PaperPlus KG | G11: {=VLOOKUP($C11,$I$6:$J$9,2,TRUE())} -> 0
A12: {='Bestellungen'!A10} -> B007 | B12: {='Bestellungen'!B10} -> A005 | C12: {='Bestellungen'!D10} -> 15 | D12: {=VLOOKUP($B12,'Stammdaten_Artikel'!$A$4:$F$23,2,FALSE())} -> USB-C Kabel | E12: {=VLOOKUP(B12,'Stammdaten_Artikel'!$A$4:$F$23,3,FALSE)} -> IT-Zubehoer | F12: {=VLOOKUP(B12,'Stammdaten_Artikel'!$A$4:$F$23,4,FALSE)} -> KabelPro AG | G12: {=VLOOKUP($C12,$I$6:$J$9,2,TRUE())} -> 0.05
A13: {='Bestellungen'!A11} -> B008 | B13: {='Bestellungen'!B11} -> A004 | C13: {='Bestellungen'!D11} -> 15 | D13: {=VLOOKUP($B13,'Stammdaten_Artikel'!$A$4:$F$23,2,FALSE())} -> Maus optisch | E13: {=VLOOKUP(B13,'Stammdaten_Artikel'!$A$4:$F$23,3,FALSE)} -> Elektronik | F13: {=VLOOKUP(B13,'Stammdaten_Artikel'!$A$4:$F$23,4,FALSE)} -> TechSupply GmbH | G13: {=VLOOKUP($C13,$I$6:$J$9,2,TRUE())} -> 0.05
A14: {='Bestellungen'!A12} -> B009 | B14: {='Bestellungen'!B12} -> A015 | C14: {='Bestellungen'!D12} -> 5 | D14: {=VLOOKUP($B14,'Stammdaten_Artikel'!$A$4:$F$23,2,FALSE())} -> Kartonbox klein | E14: {=VLOOKUP(B14,'Stammdaten_Artikel'!$A$4:$F$23,3,FALSE)} -> Verpackung | F14: {=VLOOKUP(B14,'Stammdaten_Artikel'!$A$4:$F$23,4,FALSE)} -> PackIt GmbH | G14: {=VLOOKUP($C14,$I$6:$J$9,2,TRUE())} -> 0
A15: {='Bestellungen'!A13} -> B010 | B15: {='Bestellungen'!B13} -> A020 | C15: {='Bestellungen'!D13} -> 40 | D15: {=VLOOKUP($B15,'Stammdaten_Artikel'!$A$4:$F$23,2,FALSE())} -> Webcam | E15: {=VLOOKUP(B15,'Stammdaten_Artikel'!$A$4:$F$23,3,FALSE)} -> Elektronik | F15: {=VLOOKUP(B15,'Stammdaten_Artikel'!$A$4:$F$23,4,FALSE)} -> TechSupply GmbH | G15: {=VLOOKUP($C15,$I$6:$J$9,2,TRUE())} -> 0.15
A16: {='Bestellungen'!A14} -> B011 | B16: {='Bestellungen'!B14} -> A003 | C16: {='Bestellungen'!D14} -> 50 | D16: {=VLOOKUP($B16,'Stammdaten_Artikel'!$A$4:$F$23,2,FALSE())} -> Tastatur kabellos | E16: {=VLOOKUP(B16,'Stammdaten_Artikel'!$A$4:$F$23,3,FALSE)} -> Elektronik | F16: {=VLOOKUP(B16,'Stammdaten_Artikel'!$A$4:$F$23,4,FALSE)} -> TechSupply GmbH | G16: {=VLOOKUP($C16,$I$6:$J$9,2,TRUE())} -> 0.15
A17: {='Bestellungen'!A15} -> B012 | B17: {='Bestellungen'!B15} -> A008 | C17: {='Bestellungen'!D15} -> 20 | D17: {=VLOOKUP($B17,'Stammdaten_Artikel'!$A$4:$F$23,2,FALSE())} -> Kugelschreiber | E17: {=VLOOKUP(B17,'Stammdaten_Artikel'!$A$4:$F$23,3,FALSE)} -> Bueromaterial | F17: {=VLOOKUP(B17,'Stammdaten_Artikel'!$A$4:$F$23,4,FALSE)} -> PaperPlus KG | G17: {=VLOOKUP($C17,$I$6:$J$9,2,TRUE())} -> 0.05
A18: {='Bestellungen'!A16} -> B013 | B18: {='Bestellungen'!B16} -> A006 | C18: {='Bestellungen'!D16} -> 15 | D18: {=VLOOKUP($B18,'Stammdaten_Artikel'!$A$4:$F$23,2,FALSE())} -> Headset | E18: {=VLOOKUP(B18,'Stammdaten_Artikel'!$A$4:$F$23,3,FALSE)} -> Elektronik | F18: {=VLOOKUP(B18,'Stammdaten_Artikel'!$A$4:$F$23,4,FALSE)} -> TechSupply GmbH | G18: {=VLOOKUP($C18,$I$6:$J$9,2,TRUE())} -> 0.05
A19: {='Bestellungen'!A17} -> B014 | B19: {='Bestellungen'!B17} -> A009 | C19: {='Bestellungen'!D17} -> 5 | D19: {=VLOOKUP($B19,'Stammdaten_Artikel'!$A$4:$F$23,2,FALSE())} -> Ordner A4 | E19: {=VLOOKUP(B19,'Stammdaten_Artikel'!$A$4:$F$23,3,FALSE)} -> Bueromaterial | F19: {=VLOOKUP(B19,'Stammdaten_Artikel'!$A$4:$F$23,4,FALSE)} -> PaperPlus KG | G19: {=VLOOKUP($C19,$I$6:$J$9,2,TRUE())} -> 0
A20: {='Bestellungen'!A18} -> B015 | B20: {='Bestellungen'!B18} -> A006 | C20: {='Bestellungen'!D18} -> 10 | D20: {=VLOOKUP($B20,'Stammdaten_Artikel'!$A$4:$F$23,2,FALSE())} -> Headset | E20: {=VLOOKUP(B20,'Stammdaten_Artikel'!$A$4:$F$23,3,FALSE)} -> Elektronik | F20: {=VLOOKUP(B20,'Stammdaten_Artikel'!$A$4:$F$23,4,FALSE)} -> TechSupply GmbH | G20: {=VLOOKUP($C20,$I$6:$J$9,2,TRUE())} -> 0.05
B21: A007 | E21: {=VLOOKUP(B21,'Stammdaten_Artikel'!$A$4:$F$23,3,FALSE)} -> Bueromaterial | F21: {=VLOOKUP(B21,'Stammdaten_Artikel'!$A$4:$F$23,4,FALSE)} -> PaperPlus KG | G21: {=VLOOKUP($C21,$I$6:$J$9,2,TRUE())} -> 0
B22: A008 | E22: {=VLOOKUP(B22,'Stammdaten_Artikel'!$A$4:$F$23,3,FALSE)} -> Bueromaterial | F22: {=VLOOKUP(B22,'Stammdaten_Artikel'!$A$4:$F$23,4,FALSE)} -> PaperPlus KG | G22: {=VLOOKUP($C22,$I$6:$J$9,2,TRUE())} -> 0
B23: A009 | E23: {=VLOOKUP(B23,'Stammdaten_Artikel'!$A$4:$F$23,3,FALSE)} -> Bueromaterial | F23: {=VLOOKUP(B23,'Stammdaten_Artikel'!$A$4:$F$23,4,FALSE)} -> PaperPlus KG | G23: {=VLOOKUP($C23,$I$6:$J$9,2,TRUE())} -> 0
B24: A010 | E24: {=VLOOKUP(B24,'Stammdaten_Artikel'!$A$4:$F$23,3,FALSE)} -> Bueromaterial | F24: {=VLOOKUP(B24,'Stammdaten_Artikel'!$A$4:$F$23,4,FALSE)} -> OfficeTech GmbH | G24: {=VLOOKUP($C24,$I$6:$J$9,2,TRUE())} -> 0
B25: A011 | E25: {=VLOOKUP(B25,'Stammdaten_Artikel'!$A$4:$F$23,3,FALSE)} -> Werkzeug | F25: {=VLOOKUP(B25,'Stammdaten_Artikel'!$A$4:$F$23,4,FALSE)} -> WerkzeugWelt AG | G25: {=VLOOKUP($C25,$I$6:$J$9,2,TRUE())} -> 0
B26: A012 | E26: {=VLOOKUP(B26,'Stammdaten_Artikel'!$A$4:$F$23,3,FALSE)} -> Werkzeug | F26: {=VLOOKUP(B26,'Stammdaten_Artikel'!$A$4:$F$23,4,FALSE)} -> WerkzeugWelt AG | G26: {=VLOOKUP($C26,$I$6:$J$9,2,TRUE())} -> 0
B27: A013 | E27: {=VLOOKUP(B27,'Stammdaten_Artikel'!$A$4:$F$23,3,FALSE)} -> Werkzeug | F27: {=VLOOKUP(B27,'Stammdaten_Artikel'!$A$4:$F$23,4,FALSE)} -> SafetyFirst GmbH | G27: {=VLOOKUP($C27,$I$6:$J$9,2,TRUE())} -> 0
B28: A014 | E28: {=VLOOKUP(B28,'Stammdaten_Artikel'!$A$4:$F$23,3,FALSE)} -> Werkzeug | F28: {=VLOOKUP(B28,'Stammdaten_Artikel'!$A$4:$F$23,4,FALSE)} -> SafetyFirst GmbH | G28: {=VLOOKUP($C28,$I$6:$J$9,2,TRUE())} -> 0
B29: A015 | E29: {=VLOOKUP(B29,'Stammdaten_Artikel'!$A$4:$F$23,3,FALSE)} -> Verpackung | F29: {=VLOOKUP(B29,'Stammdaten_Artikel'!$A$4:$F$23,4,FALSE)} -> PackIt GmbH | G29: {=VLOOKUP($C29,$I$6:$J$9,2,TRUE())} -> 0
B30: A016 | E30: {=VLOOKUP(B30,'Stammdaten_Artikel'!$A$4:$F$23,3,FALSE)} -> Verpackung | F30: {=VLOOKUP(B30,'Stammdaten_Artikel'!$A$4:$F$23,4,FALSE)} -> PackIt GmbH | G30: {=VLOOKUP($C30,$I$6:$J$9,2,TRUE())} -> 0
B31: A017 | E31: {=VLOOKUP(B31,'Stammdaten_Artikel'!$A$4:$F$23,3,FALSE)} -> Verpackung | F31: {=VLOOKUP(B31,'Stammdaten_Artikel'!$A$4:$F$23,4,FALSE)} -> PackIt GmbH | G31: {=VLOOKUP($C31,$I$6:$J$9,2,TRUE())} -> 0
B32: A018 | E32: {=VLOOKUP(B32,'Stammdaten_Artikel'!$A$4:$F$23,3,FALSE)} -> Verpackung | F32: {=VLOOKUP(B32,'Stammdaten_Artikel'!$A$4:$F$23,4,FALSE)} -> PackIt GmbH | G32: {=VLOOKUP($C32,$I$6:$J$9,2,TRUE())} -> 0
... B34: A020 | E34: {=VLOOKUP(B34,'Stammdaten_Artikel'!$A$4:$F$23,3,FALSE)} -> Elektronik | F34: {=VLOOKUP(B34,'Stammdaten_Artikel'!$A$4:$F$23,4,FALSE)} -> TechSupply GmbH | G34: {=VLOOKUP($C34,$I$6:$J$9,2,TRUE())} -> 0

Sheet 02_INDEX_VERGLEICH
A1: 02 | INDEX und VERGLEICH
A3: A) INDEX/VERGLEICH als SVERWEIS-Ersatz
A5: Bestell-ID | B5: Artikel-ID | C5: Menge | D5: Artikelname (INDEX/VERGLEICH) | E5: Kategorie (Uebung)
A6: {='Bestellungen'!A4} -> B001 | B6: {='Bestellungen'!B4} -> A004 | C6: {='Bestellungen'!D4} -> 12 | D6: {=INDEX('Stammdaten_Artikel'!$B$4:$B$23,MATCH($B6,'Stammdaten_Artikel'!$A$4:$A$23,0))} -> Maus optisch | E6: {=INDEX('Stammdaten_Artikel'!$C$4:$C$23,MATCH(B6,'Stammdaten_Artikel'!$A$4:$A$23,0))} -> Elektronik
A7: {='Bestellungen'!A5} -> B002 | B7: {='Bestellungen'!B5} -> A004 | C7: {='Bestellungen'!D5} -> 5 | D7: {=INDEX('Stammdaten_Artikel'!$B$4:$B$23,MATCH($B7,'Stammdaten_Artikel'!$A$4:$A$23,0))} -> Maus optisch | E7: {=INDEX('Stammdaten_Artikel'!$C$4:$C$23,MATCH(B7,'Stammdaten_Artikel'!$A$4:$A$23,0))} -> Elektronik
A8: {='Bestellungen'!A6} -> B003 | B8: {='Bestellungen'!B6} -> A001 | C8: {='Bestellungen'!D6} -> 5 | D8: {=INDEX('Stammdaten_Artikel'!$B$4:$B$23,MATCH($B8,'Stammdaten_Artikel'!$A$4:$A$23,0))} -> Laptop 14 Zoll | E8: {=INDEX('Stammdaten_Artikel'!$C$4:$C$23,MATCH(B8,'Stammdaten_Artikel'!$A$4:$A$23,0))} -> Elektronik
A9: {='Bestellungen'!A7} -> B004 | B9: {='Bestellungen'!B7} -> A020 | C9: {='Bestellungen'!D7} -> 30 | D9: {=INDEX('Stammdaten_Artikel'!$B$4:$B$23,MATCH($B9,'Stammdaten_Artikel'!$A$4:$A$23,0))} -> Webcam | E9: {=INDEX('Stammdaten_Artikel'!$C$4:$C$23,MATCH(B9,'Stammdaten_Artikel'!$A$4:$A$23,0))} -> Elektronik
A10: {='Bestellungen'!A8} -> B005 | B10: {='Bestellungen'!B8} -> A018 | C10: {='Bestellungen'!D8} -> 10 | D10: {=INDEX('Stammdaten_Artikel'!$B$4:$B$23,MATCH($B10,'Stammdaten_Artikel'!$A$4:$A$23,0))} -> Luftpolsterfolie | E10: {=INDEX('Stammdaten_Artikel'!$C$4:$C$23,MATCH(B10,'Stammdaten_Artikel'!$A$4:$A$23,0))} -> Verpackung
A11: {='Bestellungen'!A9} -> B006 | B11: {='Bestellungen'!B9} -> A009 | C11: {='Bestellungen'!D9} -> 8 | D11: {=INDEX('Stammdaten_Artikel'!$B$4:$B$23,MATCH($B11,'Stammdaten_Artikel'!$A$4:$A$23,0))} -> Ordner A4 | E11: {=INDEX('Stammdaten_Artikel'!$C$4:$C$23,MATCH(B11,'Stammdaten_Artikel'!$A$4:$A$23,0))} -> Bueromaterial
A12: {='Bestellungen'!A10} -> B007 | B12: {='Bestellungen'!B10} -> A005 | C12: {='Bestellungen'!D10} -> 15 | D12: {=INDEX('Stammdaten_Artikel'!$B$4:$B$23,MATCH($B12,'Stammdaten_Artikel'!$A$4:$A$23,0))} -> USB-C Kabel | E12: {=INDEX('Stammdaten_Artikel'!$C$4:$C$23,MATCH(B12,'Stammdaten_Artikel'!$A$4:$A$23,0))} -> IT-Zubehoer
A13: {='Bestellungen'!A11} -> B008 | B13: {='Bestellungen'!B11} -> A004 | C13: {='Bestellungen'!D11} -> 15 | D13: {=INDEX('Stammdaten_Artikel'!$B$4:$B$23,MATCH($B13,'Stammdaten_Artikel'!$A$4:$A$23,0))} -> Maus optisch | E13: {=INDEX('Stammdaten_Artikel'!$C$4:$C$23,MATCH(B13,'Stammdaten_Artikel'!$A$4:$A$23,0))} -> Elektronik
A14: {='Bestellungen'!A12} -> B009 | B14: {='Bestellungen'!B12} -> A015 | C14: {='Bestellungen'!D12} -> 5 | D14: {=INDEX('Stammdaten_Artikel'!$B$4:$B$23,MATCH($B14,'Stammdaten_Artikel'!$A$4:$A$23,0))} -> Kartonbox klein | E14: {=INDEX('Stammdaten_Artikel'!$C$4:$C$23,MATCH(B14,'Stammdaten_Artikel'!$A$4:$A$23,0))} -> Verpackung
A15: {='Bestellungen'!A13} -> B010 | B15: {='Bestellungen'!B13} -> A020 | C15: {='Bestellungen'!D13} -> 40 | D15: {=INDEX('Stammdaten_Artikel'!$B$4:$B$23,MATCH($B15,'Stammdaten_Artikel'!$A$4:$A$23,0))} -> Webcam | E15: {=INDEX('Stammdaten_Artikel'!$C$4:$C$23,MATCH(B15,'Stammdaten_Artikel'!$A$4:$A$23,0))} -> Elektronik
A16: {='Bestellungen'!A14} -> B011 | B16: {='Bestellungen'!B14} -> A003 | C16: {='Bestellungen'!D14} -> 50 | D16: {=INDEX('Stammdaten_Artikel'!$B$4:$B$23,MATCH($B16,'Stammdaten_Artikel'!$A$4:$A$23,0))} -> Tastatur kabellos | E16: {=INDEX('Stammdaten_Artikel'!$C$4:$C$23,MATCH(B16,'Stammdaten_Artikel'!$A$4:$A$23,0))} -> Elektronik
A17: {='Bestellungen'!A15} -> B012 | B17: {='Bestellungen'!B15} -> A008 | C17: {='Bestellungen'!D15} -> 20 | D17: {=INDEX('Stammdaten_Artikel'!$B$4:$B$23,MATCH($B17,'Stammdaten_Artikel'!$A$4:$A$23,0))} -> Kugelschreiber | E17: {=INDEX('Stammdaten_Artikel'!$C$4:$C$23,MATCH(B17,'Stammdaten_Artikel'!$A$4:$A$23,0))} -> Bueromaterial
... A20: {='Bestellungen'!A18} -> B015 | B20: {='Bestellungen'!B18} -> A006 | C20: {='Bestellungen'!D18} -> 10 | D20: {=INDEX('Stammdaten_Artikel'!$B$4:$B$23,MATCH($B20,'Stammdaten_Artikel'!$A$4:$A$23,0))} -> Headset | E20: {=INDEX('Stammdaten_Artikel'!$C$4:$C$23,MATCH(B20,'Stammdaten_Artikel'!$A$4:$A$23,0))} -> Elektronik

Sheet 03_XVERWEIS_XVERGLEICH
A1: 03 | XVERWEIS und XVERGLEICH
A3: A) XVERWEIS - Suche nach links ohne Spaltenzaehlen
A5: Artikelname (Eingabe): | C5: Schraubendreher-Set
A6: Gefundene Artikel-ID (XVERWEIS): | C6: {=_xlfn.XLOOKUP(C5,'Stammdaten_Artikel'!$B$4:$B$23,'Stammdaten_Artikel'!$A$4:$A$23)} -> A012
A9: Artikelname (Eingabe): | C9: Aktenvernichter
A10: Uebung: Kategorie finden (XVERWEIS): | C10: Uebung: XVERWEIS schreiben
A13: B) Der Parameter wenn_nicht_gefunden
A15: Artikel-ID (Eingabe, existiert NICHT): | C15: A099
A16: Ergebnis mit wenn_nicht_gefunden: | C16: {=_xlfn.XLOOKUP(C15,'Stammdaten_Artikel'!$A$4:$A$23,'Stammdaten_Artikel'!$B$4:$B$23,"Artikel nicht im Stamm gefunden")} -> Artikel nicht im Stamm gefunden
A19: C) Suchmodus -1: von unten nach oben suchen
A21: Artikel-ID (Eingabe): | C21: A001
A22: Status der letzten Bestellung (XVERWEIS, Suchmodus -1): | C22: {=_xlfn.XLOOKUP(C21,'Bestellungen'!$B$4:$B$43,'Bestellungen'!$F$4:$F$43,"keine Bestellung gefunden",0,-1)} -> Offen
